Workbook

Sheet Companies
A1: Greek Pantheon Tech Directory
A2: 150 fictional tech companies, 10 products each. All company, product and specification data is fictional sample data.
B4: LEGEND
B5: Color | C5: Company Type | D5: Count
C6: Headphones & Earbuds | D6: =COUNTIF($C$14:$C$163,C6)
C7: Laptops | D7: =COUNTIF($C$14:$C$163,C7)
C8: Smartphones & Tablets | D8: =COUNTIF($C$14:$C$163,C8)
C9: Computer Hardware | D9: =COUNTIF($C$14:$C$163,C9)
C10: Total | D10: =SUM(D6:D9)
A13: # | B13: Company | C13: Category | D13: Other Names (short names, misspellings) | E13: Standard Warranty | F13: Company Certifications | G13: Use-Case Focus | H13: Product Categories | I13: Product 1 | J13: Price 1 | K13: Product 2 | L13: Price 2 | M13: Product 3 | N13: Price 3 | O13: Product 4 | P13: Price 4 | Q13: Product 5 | R13: Price 5 | S13: Product 6 | T13: Price 6 | U13: Product 7 | V13: Price 7 | W13: Product 8 | X13: Price 8 | Y13: Product 9 | Z13: Price 9 | AA13: Product 10 | AB13: Price 10 | AC13: Lowest Price | AD13: Highest Price | AE13: Average Price | AF13: Return Policy (days) (generated)
A14: 1 | B14: Morpheus | C14: Headphones & Earbuds | D14: Morpheus Audio; MORPHEUS; Morpheuss; Morppheus | E14: 1 year limited | F14: ISO 9001, ISO 14001, ISO 45001 | G14: travel, running, audiophile, outdoor | H14: Earbuds, Headphones, Headset | I14: Morpheus Onyx Air Kids Headphones | J14: 22.99 | K14: Morpheus Nova Ultra Wired In-Ear Monitors | L14: 54.99 | M14: Morpheus Spark Sport Earbuds | N14: 120.99 | O14: Morpheus Arc Open-Ear Earbuds | P14: 156.99 | Q14: Morpheus Quanta X Gaming Headset | R14: 171.99 | S14: Morpheus Pulse X Bone Conduction Headphones | T14: 195.99 | U14: Morpheus Rift Plus ANC Over-Ear Headphones | V14: 205.99 | W14: Morpheus Vibe Lite True Wireless Earbuds | X14: 244.99 | Y14: Morpheus Onyx Air Studio Monitor Headphones | Z14: 374.99 | AA14: Morpheus Onyx Lite Audiophile Planar Headphones | AB14: 1063.99 | AC14: =MIN(J14,L14,N14,P14,R14,T14,V14,X14,Z14,AB14) | AD14: =MAX(J14,L14,N14,P14,R14,T14,V14,X14,Z14,AB14) | AE14: =AVERAGE(J14,L14,N14,P14,R14,T14,V14,X14,Z14,AB14) | AF14: 60
A15: 2 | B15: Carpo | C15: Headphones & Earbuds | D15: Carpo Audio; CARPO; Carpoo; Crapo | E15: 1 year limited | F15: ISO 9001, WEEE Registered, ISO/IEC 27001 | G15: travel, running, school, commute | H15: Earbuds, Headphones | I15: Carpo Apex Plus Kids Headphones | J15: 43.99 | K15: Carpo Nova On-Ear Headphones | L15: 59.99 | M15: Carpo Quanta Air Bone Conduction Headphones | N15: 134.99 | O15: Carpo Lumen Pro Open-Ear Earbuds | P15: 136.99 | Q15: Carpo Flux Pro Sport Earbuds | R15: 153.99 | S15: Carpo Nova Air Wired In-Ear Monitors | T15: 183.99 | U15: Carpo Nova Plus Studio Monitor Headphones | V15: 213.99 | W15: Carpo Nova ANC Over-Ear Headphones | X15: 265.99 | Y15: Carpo Halo Max Sleep Earbuds | Z15: 274.99 | AA15: Carpo Lumen Air Audiophile Planar Headphones | AB15: 341.99 | AC15: =MIN(J15,L15,N15,P15,R15,T15,V15,X15,Z15,AB15) | AD15: =MAX(J15,L15,N15,P15,R15,T15,V15,X15,Z15,AB15) | AE15: =AVERAGE(J15,L15,N15,P15,R15,T15,V15,X15,Z15,AB15) | AF15: 30
A16: 3 | B16: Himeros | C16: Headphones & Earbuds | D16: Himeros Audio; HIMEROS; Himeroos; Himeeros | E16: 1 year limited | F16: ISO 9001, ISO 45001, ISO/IEC 27001 | G16: travel, running, school, outdoor | H16: Earbuds, Headphones, Headset | I16: Himeros Volt SE Kids Headphones | J16: 45.99 | K16: Himeros Echo SE Sport Earbuds | L16: 63.99 | M16: Himeros Wave Max Bone Conduction Headphones | N16: 132.99 | O16: Himeros Halo Pro Sleep Earbuds | P16: 161.99 | Q16: Himeros Arc True Wireless Earbuds | R16: 166.99 | S16: Himeros Sable SE On-Ear Headphones | T16: 179.99 | U16: Himeros Flux Studio Monitor Headphones | V16: 195.99 | W16: Himeros Aeon Lite Open-Ear Earbuds | X16: 215.99 | Y16: Himeros Sable Gaming Headset | Z16: 221.99 | AA16: Himeros Aeon Audiophile Planar Headphones | AB16: 1139.99 | AC16: =MIN(J16,L16,N16,P16,R16,T16,V16,X16,Z16,AB16) | AD16: =MAX(J16,L16,N16,P16,R16,T16,V16,X16,Z16,AB16) | AE16: =AVERAGE(J16,L16,N16,P16,R16,T16,V16,X16,Z16,AB16) | AF16: 30
A17: 4 | B17: Doris | C17: Headphones & Earbuds | D17: Doris Audio; DORIS; Dooris; Doirs | E17: 1 year limited | F17: ISO 9001, WEEE Registered, ISO 14001 | G17: travel, commute, school, everyday | H17: Earbuds, Headphones, Headset | I17: Doris Halo SE Kids Headphones | J17: 48.99 | K17: Doris Echo X On-Ear Headphones | L17: 72.99 | M17: Doris Rift Ultra True Wireless Earbuds | N17: 115.99 | O17: Doris Halo Wired In-Ear Monitors | P17: 165.99 | Q17: Doris Vertex Air Sleep Earbuds | R17: 171.99 | S17: Doris Echo Lite Bone Conduction Headphones | T17: 193.99 | U17: Doris Echo Plus Gaming Headset | V17: 325.99 | W17: Doris Pulse SE ANC Over-Ear Headphones | X17: 342.99 | Y17: Doris Rift Air Studio Monitor Headphones | Z17: 355.99 | AA17: Doris Vibe Pro Audiophile Planar Headphones | AB17: 1294.99 | AC17: =MIN(J17,L17,N17,P17,R17,T17,V17,X17,Z17,AB17) | AD17: =MAX(J17,L17,N17,P17,R17,T17,V17,X17,Z17,AB17) | AE17: =AVERAGE(J17,L17,N17,P17,R17,T17,V17,X17,Z17,AB17) | AF17: 60
A18: 5 | B18: Deimos | C18: Headphones & Earbuds | D18: Deimos Audio; DEIMOS; Deimmos; Diemos | E18: 1 year limited | F18: ISO 9001, RoHS Compliant, ISO 45001 | G18: commute, running, travel, everyday | H18: Earbuds, Headphones | I18: Deimos Aeon X On-Ear Headphones | J18: 60.99 | K18: Deimos Quanta X Sport Earbuds | L18: 68.99 | M18: Deimos Crest Bone Conduction Headphones | N18: 83.99 | O18: Deimos Lumen X True Wireless Earbuds | P18: 111.99 | Q18: Deimos Aeon Plus Open-Ear Earbuds | R18: 154.99 | S18: Deimos Halo Plus Sleep Earbuds | T18: 164.99 | U18: Deimos Core SE Studio Monitor Headphones | V18: 220.99 | W18: Deimos Apex X ANC Over-Ear Headphones | X18: 362.99 | Y18: Deimos Rift Wired In-Ear Monitors | Z18: 398.99 | AA18: Deimos Orbit Plus Audiophile Planar Headphones | AB18: 1455.99 | AC18: =MIN(J18,L18,N18,P18,R18,T18,V18,X18,Z18,AB18) | AD18: =MAX(J18,L18,N18,P18,R18,T18,V18,X18,Z18,AB18) | AE18: =AVERAGE(J18,L18,N18,P18,R18,T18,V18,X18,Z18,AB18) | AF18: 15
A19: 6 | B19: Asteria | C19: Headphones & Earbuds | D19: Asteria Audio; ASTERIA; Asteri; Atseria | E19: 1 year limited | F19: ISO 9001, WEEE Registered, ISO 45001 | G19: commute, travel, everyday, running | H19: Earbuds, Headphones, Headset | I19: Asteria Apex Air On-Ear Headphones | J19: 60.99 | K19: Asteria Core Sport Earbuds | L19: 72.99 | M19: Asteria Core Max Gaming Headset | N19: 127.99 | O19: Asteria Volt Max Wired In-Ear Monitors | P19: 139.99 | Q19: Asteria Drift Air Bone Conduction Headphones | R19: 181.99 | S19: Asteria Halo Plus True Wireless Earbuds | T19: 202.99 | U19: Asteria Aeon Air ANC Over-Ear Headphones | V19: 228.99 | W19: Asteria Rift Studio Monitor Headphones | X19: 251.99 | Y19: Asteria Prism X Sleep Earbuds | Z19: 278.99 | AA19: Asteria Blaze Air Audiophile Planar Headphones | AB19: 517.99 | AC19: =MIN(J19,L19,N19,P19,R19,T19,V19,X19,Z19,AB19) | AD19: =MAX(J19,L19,N19,P19,R19,T19,V19,X19,Z19,AB19) | AE19: =AVERAGE(J19,L19,N19,P19,R19,T19,V19,X19,Z19,AB19) | AF19: 15
A20: 7 | B20: Tethys | C20: Headphones & Earbuds | D20: Tethys Audio; TETHYS; Tethyys; Teethys | E20: 1 year limited | F20: ISO 9001, ISO/IEC 27001, ISO 14001 | G20: travel, commute, school, running | H20: Earbuds, Headphones, Headset | I20: Tethys Pulse Kids Headphones | J20: 53.99 | K20: Tethys Quanta Lite Sport Earbuds | L20: 57.99 | M20: Tethys Pulse Plus On-Ear Headphones | N20: 69.99 | O20: Tethys Vertex Lite Gaming Headset | P20: 123.99 | Q20: Tethys Drift Max Sleep Earbuds | R20: 131.99 | S20: Tethys Axis SE Bone Conduction Headphones | T20: 148.99 | U20: Tethys Quanta Plus ANC Over-Ear Headphones | V20: 168.99 | W20: Tethys Blaze Ultra Studio Monitor Headphones | X20: 180.99 | Y20: Tethys Echo Plus True Wireless Earbuds | Z20: 187.99 | AA20: Tethys Prism Plus Audiophile Planar Headphones | AB20: 383.99 | AC20: =MIN(J20,L20,N20,P20,R20,T20,V20,X20,Z20,AB20) | AD20: =MAX(J20,L20,N20,P20,R20,T20,V20,X20,Z20,AB20) | AE20: =AVERAGE(J20,L20,N20,P20,R20,T20,V20,X20,Z20,AB20) | AF20: 30
A21: 8 | B21: Menoetius | C21: Headphones & Earbuds | D21: Menoetius Audio; MENOETIUS; Menoetuis; Menoeetius | E21: 1 year limited | F21: ISO 9001, ISO/IEC 27001, WEEE Registered | G21: commute, travel, everyday, running | H21: Earbuds, Headphones, Headset | I21: Menoetius Sable Lite On-Ear Headphones | J21: 99.99 | K21: Menoetius Pulse Pro True Wireless Earbuds | L21: 105.99 | M21: Menoetius Strata Open-Ear Earbuds | N21: 175.99 | O21: Menoetius Sable Pro Bone Conduction Headphones | P21: 183.99 | Q21: Menoetius Wave Gaming Headset | R21: 184.99 | S21: Menoetius Pulse Lite Sleep Earbuds | T21: 203.99 | U21: Menoetius Volt Max Wired In-Ear Monitors | V21: 249.99 | W21: Menoetius Arc Pro Studio Monitor Headphones | X21: 338.99 | Y21: Menoetius Strata Pro ANC Over-Ear Headphones | Z21: 490.99 | AA21: Menoetius Sable SE Audiophile Planar Headphones | AB21: 978.99 | AC21: =MIN(J21,L21,N21,P21,R21,T21,V21,X21,Z21,AB21) | AD21: =MAX(J21,L21,N21,P21,R21,T21,V21,X21,Z21,AB21) | AE21: =AVERAGE(J21,L21,N21,P21,R21,T21,V21,X21,Z21,AB21) | AF21: 30
A22: 9 | B22: Phosphorus | C22: Headphones & Earbuds | D22: Phosphorus Audio; PHOSPHORUS; Phosphrous; Phosphhorus | E22: 1 year limited | F22: ISO 9001, RoHS Compliant, ISO 45001 | G22: travel, school, running, commute | H22: Earbuds, Headphones, Headset | I22: Phosphorus Core Kids Headphones | J22: 30.99 | K22: Phosphorus Quanta Max Gaming Headset | L22: 107.99 | M22: Phosphorus Nimbus X Sleep Earbuds | N22: 127.99 | O22: Phosphorus Crest Air Sport Earbuds | P22: 149.99 | Q22: Phosphorus Flux X ANC Over-Ear Headphones | R22: 167.99 | S22: Phosphorus Lumen Max Studio Monitor Headphones | T22: 189.99 | U22: Phosphorus Zen Open-Ear Earbuds | V22: 215.99 | W22: Phosphorus Volt Plus Wired In-Ear Monitors | X22: 236.99 | Y22: Phosphorus Vertex On-Ear Headphones | Z22: 239.99 | AA22: Phosphorus Rift Air Audiophile Planar Headphones | AB22: 1362.99 | AC22: =MIN(J22,L22,N22,P22,R22,T22,V22,X22,Z22,AB22) | AD22: =MAX(J22,L22,N22,P22,R22,T22,V22,X22,Z22,AB22) | AE22: =AVERAGE(J22,L22,N22,P22,R22,T22,V22,X22,Z22,AB22) | AF22: 15
A23: 10 | B23: Hedone | C23: Headphones & Earbuds | D23: Hedone Audio; HEDONE; Hedonee; Hedonne | E23: 1 year limited | F23: ISO 9001, ISO 14001, ISO/IEC 27001 | G23: running, travel, everyday, commute | H23: Earbuds, Headphones, Headset | I23: Hedone Halo SE Gaming Headset | J23: 113.99 | K23: Hedone Prism Pro Sport Earbuds | L23: 115.99 | M23: Hedone Blaze Max Sleep Earbuds | N23: 129.99 | O23: Hedone Nimbus Max On-Ear Headphones | P23: 141.99 | Q23: Hedone Aria Bone Conduction Headphones | R23: 148.99 | S23: Hedone Apex Lite Open-Ear Earbuds | T23: 175.99 | U23: Hedone Lumen Max True Wireless Earbuds | V23: 205.99 | W23: Hedone Sable X Studio Monitor Headphones | X23: 318.99 | Y23: Hedone Drift Plus Wired In-Ear Monitors | Z23: 324.99 | AA23: Hedone Prism SE Audiophile Planar Headphones | AB23: 1336.99 | AC23: =MIN(J23,L23,N23,P23,R23,T23,V23,X23,Z23,AB23) | AD23: =MAX(J23,L23,N23,P23,R23,T23,V23,X23,Z23,AB23) | AE23: =AVERAGE(J23,L23,N23,P23,R23,T23,V23,X23,Z23,AB23) | AF23: 30
A24: 11 | B24: Hebe | C24: Headphones & Earbuds | D24: Hebe Audio; HEBE; Heb; Hebbe | E24: 1 year limited | F24: ISO 9001, ISO 45001, RoHS Compliant | G24: travel, commute, audiophile, school | H24: Earbuds, Headphones, Headset | I24: Hebe Arc Ultra Wired In-Ear Monitors | J24: 37.99 | K24: Hebe Apex X Kids Headphones | L24: 50.99 | M24: Hebe Drift True Wireless Earbuds | N24: 85.99 | O24: Hebe Aeon SE Open-Ear Earbuds | P24: 96.99 | Q24: Hebe Vibe On-Ear Headphones | R24: 108.99 | S24: Hebe Axis SE Gaming Headset | T24: 147.99 | U24: Hebe Prism Pro Sleep Earbuds | V24: 270.99 | W24: Hebe Nimbus Pro ANC Over-Ear Headphones | X24: 401.99 | Y24: Hebe Strata Studio Monitor Headphones | Z24: 482.99 | AA24: Hebe Nova Pro Audiophile Planar Headphones | AB24: 984.99 | AC24: =MIN(J24,L24,N24,P24,R24,T24,V24,X24,Z24,AB24) | AD24: =MAX(J24,L24,N24,P24,R24,T24,V24,X24,Z24,AB24) | AE24: =AVERAGE(J24,L24,N24,P24,R24,T24,V24,X24,Z24,AB24) | AF24: 30
A25: 12 | B25: Glaucus | C25: Headphones & Earbuds | D25: Glaucus Audio; GLAUCUS; Glaucu; Glauucus | E25: 1 year limited | F25: ISO 9001, ISO 45001, RoHS Compliant | G25: travel, running, commute, school | H25: Earbuds, Headphones, Headset | I25: Glaucus Aria Air Kids Headphones | J25: 45.99 | K25: Glaucus Sable Ultra Open-Ear Earbuds | L25: 112.99 | M25: Glaucus Aria Air Bone Conduction Headphones | N25: 156.99 | O25: Glaucus Quanta Lite True Wireless Earbuds | P25: 162.99 | Q25: Glaucus Zen Ultra Sport Earbuds | R25: 190.99 | S25: Glaucus Orbit Air On-Ear Headphones | T25: 228.99 | U25: Glaucus Drift Pro Gaming Headset | V25: 296.99 | W25: Glaucus Core Pro ANC Over-Ear Headphones | X25: 378.99 | Y25: Glaucus Strata Ultra Studio Monitor Headphones | Z25: 478.99 | AA25: Glaucus Onyx Air Audiophile Planar Headphones | AB25: 865.99 | AC25: =MIN(J25,L25,N25,P25,R25,T25,V25,X25,Z25,AB25) | AD25: =MAX(J25,L25,N25,P25,R25,T25,V25,X25,Z25,AB25) | AE25: =AVERAGE(J25,L25,N25,P25,R25,T25,V25,X25,Z25,AB25) | AF25: 30
... A163: 150 | B163: Artemis | C163: Computer Hardware | D163: Artemis Hardware; ARTEMIS; Arteemis; Aretmis | E163: 2 year limited | F163: ISO 9001, RoHS Compliant, ISO/IEC 27001 | G163: gaming, PC building, workstation builds, multitasking | H163: Graphics Card, Keyboard, Memory, Motherboard, Mouse, PC Case, Power Supply, Processor, Storage, Webcam | I163: Artemis Wave Plus 32GB DDR5 RAM Kit | J163: 98.99 | K163: Artemis Volt Plus Mechanical Keyboard | L163: 120.99 | M163: Artemis Strata Gaming Mouse | N163: 121.99 | O163: Artemis Aeon Lite Mid-Tower PC Case | P163: 131.99 | Q163: Artemis Drift X 4K Webcam | R163: 155.99 | S163: Artemis Prism Max 4TB External Hard Drive | T163: 171.99 | U163: Artemis Spark Ultra 850W Power Supply | V163: 218.99 | W163: Artemis Zen Plus ATX Motherboard | X163: 264.99 | Y163: Artemis Drift Plus Desktop CPU | Z163: 299.99 | AA163: Artemis Nimbus X Graphics Card | AB163: 408.99 | AC163: =MIN(J163,L163,N163,P163,R163,T163,V163,X163,Z163,AB163) | AD163: =MAX(J163,L163,N163,P163,R163,T163,V163,X163,Z163,AB163) | AE163: =AVERAGE(J163,L163,N163,P163,R163,T163,V163,X163,Z163,AB163) | AF163: 30

Sheet Product Details
A1: Product Details and Verifiable Specifications
A2: N/A means the field does not apply to that product. Verified Comparisons are checked against the competitor data in this workbook (competitor SKU shown in brackets). | T2: Columns marked (generated) were filled by script: deterministic sample values, not source data.
B3: LEGEND
B4: Color | C4: Company Type | D4: Count
C5: Headphones & Earbuds | D5: =COUNTIF($C$13:$C$1512,C5)
C6: Laptops | D6: =COUNTIF($C$13:$C$1512,C6)
C7: Smartphones & Tablets | D7: =COUNTIF($C$13:$C$1512,C7)
C8: Computer Hardware | D8: =COUNTIF($C$13:$C$1512,C8)
C9: Total | D9: =SUM(D5:D8)
A12: SKU | B12: Company | C12: Category | D12: Product Category | E12: Product | F12: Price | G12: Other Names (short names, misspellings) | H12: Warranty | I12: Certifications | J12: Processor | K12: Graphics | L12: Display Type | M12: Resolution | N12: Ports | O12: Operating System | P12: Battery Life (hrs) | Q12: Weight (g) | R12: Verified Comparisons | S12: Use-Case Tags | T12: Availability (generated) | U12: Return Policy (days) (generated) | V12: Previous Price (generated) | W12: Price Changed On (generated) | X12: RAM (GB) (generated) | Y12: Storage (GB) (generated) | Z12: Screen Size (in) (generated) | AA12: Touchscreen (generated)
A13: MOR-001-01 | B13: Morpheus | C13: Headphones & Earbuds | D13: Headphones | E13: Morpheus Onyx Air Kids Headphones | F13: 22.99 | G13: the Onyx Air; Morpheus Onyx Air; Morppheus Onyx Air; Onyx Air headphones | H13: 1 year limited | I13: FCC, CE, Bluetooth SIG Qualified, EN 71 Toy Safety | J13: N/A | K13: N/A | L13: N/A | M13: N/A | N13: USB-C charging, 3.5mm (85 dB limited) | O13: N/A | P13: 23 | Q13: 130 | R13: Lighter than Nereus Drift Kids Headphones [NER-020-01] (130 g vs 141 g); Lower price than Hesperus Onyx SE Kids Headphones [HES-025-01] ($22.99 vs $35.99) | S13: kids, school, travel | T13: in_stock | U13: 60 | V13: 24.99 | W13: 2026-09-02 | X13: N/A | Y13: N/A | Z13: N/A | AA13: N/A
A14: MOR-001-02 | B14: Morpheus | C14: Headphones & Earbuds | D14: Earbuds | E14: Morpheus Nova Ultra Wired In-Ear Monitors | F14: 54.99 | G14: the Nova Ultra; Morpheus Nova Ultra; Morpheu Nova Ultra; Nova Ultra earbuds | H14: 1 year limited | I14: CE, RoHS, Hi-Res Audio | J14: N/A | K14: N/A | L14: N/A | M14: N/A | N14: Detachable 2-pin cable: 3.5mm | O14: N/A | P14: N/A | Q14: 36 | R14: Lower price than Chaos Axis Max Wired In-Ear Monitors [CHA-016-02] ($54.99 vs $66.99); Lighter than Carpo Nova Air Wired In-Ear Monitors [CAR-002-06] (36 g vs 40 g) | S14: audiophile, stage monitoring, music | T14: low_stock | U14: 60 | V14: 59.99 | W14: 2026-09-07 | X14: N/A | Y14: N/A | Z14: N/A | AA14: N/A
A15: MOR-001-03 | B15: Morpheus | C15: Headphones & Earbuds | D15: Earbuds | E15: Morpheus Spark Sport Earbuds | F15: 120.99 | G15: the Spark; Morpheus Spark; Morrpheus Spark; Spark earbuds | H15: 1 year limited | I15: FCC, CE, Bluetooth SIG Qualified, IPX4 | J15: N/A | K15: N/A | L15: N/A | M15: N/A | N15: USB-C charging case | O15: N/A | P15: 10 | Q15: 5 | R15: Longer battery than Ananke Strata Lite Sport Earbuds [ANA-023-02] (10 vs 9 hrs); Lighter than Hedone Prism Pro Sport Earbuds [HED-010-02] (5 g vs 7 g) | S15: gym, running, sport | T15: out_of_stock | U15: 60 | V15: 134.99 | W15: 2026-08-09 | X15: N/A | Y15: N/A | Z15: N/A | AA15: N/A
A16: MOR-001-04 | B16: Morpheus | C16: Headphones & Earbuds | D16: Earbuds | E16: Morpheus Arc Open-Ear Earbuds | F16: 156.99 | G16: the Arc; Morpheus Arc; Morphues Arc; Arc earbuds | H16: 1 year limited | I16: FCC, CE, Bluetooth SIG Qualified, IPX5 | J16: N/A | K16: N/A | L16: N/A | M16: N/A | N16: USB-C charging case | O16: N/A | P16: 9 | Q16: 10 | R16: Lighter than Asclepius Axis Max Open-Ear Earbuds [ASC-024-06] (10 g vs 11 g); Longer battery than Zeus Strata X Open-Ear Earbuds [ZEU-013-02] (9 vs 8 hrs) | S16: running, outdoor, office | T16: in_stock | U16: 60 | V16: 180.99 | W16: 2026-08-26 | X16: N/A | Y16: N/A | Z16: N/A | AA16: N/A
A17: MOR-001-05 | B17: Morpheus | C17: Headphones & Earbuds | D17: Headset | E17: Morpheus Quanta X Gaming Headset | F17: 171.99 | G17: the Quanta X; Morpheus Quanta X; Morphheus Quanta X; Quanta X headset | H17: 1 year limited | I17: FCC, CE, Bluetooth SIG Qualified | J17: N/A | K17: N/A | L17: N/A | M17: N/A | N17: USB-C, 3.5mm, 2.4GHz USB dongle | O17: N/A | P17: 42 | Q17: 363 | R17: Longer battery than Glaucus Drift Pro Gaming Headset [GLA-012-07] (42 vs 23 hrs); Lower price than Hesperus Aeon Plus Gaming Headset [HES-025-06] ($171.99 vs $241.99) | S17: gaming, streaming, voice chat | T17: in_stock | U17: 60 | V17: 189.99 | W17: 2026-08-22 | X17: N/A | Y17: N/A | Z17: N/A | AA17: N/A
A18: MOR-001-06 | B18: Morpheus | C18: Headphones & Earbuds | D18: Headphones | E18: Morpheus Pulse X Bone Conduction Headphones | F18: 195.99 | G18: the Pulse X; Morpheus Pulse X; Morrpheus Pulse X; Pulse X headphones | H18: 1 year limited | I18: FCC, CE, Bluetooth SIG Qualified, IP67 | J18: N/A | K18: N/A | L18: N/A | M18: N/A | N18: Magnetic USB charging | O18: N/A | P18: 10 | Q18: 34 | R18: Longer battery than Tartarus Volt Max Bone Conduction Headphones [TAR-017-03] (10 vs 7 hrs); Lighter than Deimos Crest Bone Conduction Headphones [DEI-005-03] (34 g vs 35 g) | S18: running, cycling, outdoor | T18: in_stock | U18: 60 | V18: 224.99 | W18: 2026-08-27 | X18: N/A | Y18: N/A | Z18: N/A | AA18: N/A
A19: MOR-001-07 | B19: Morpheus | C19: Headphones & Earbuds | D19: Headphones | E19: Morpheus Rift Plus ANC Over-Ear Headphones | F19: 205.99 | G19: the Rift Plus; Morpheus Rift Plus; Morphues Rift Plus; Rift Plus headphones | H19: 1 year limited | I19: FCC, CE, Bluetooth SIG Qualified | J19: N/A | K19: N/A | L19: N/A | M19: N/A | N19: USB-C charging and audio, 3.5mm | O19: N/A | P19: 56 | Q19: 259 | R19: Longer battery than Asclepius Rift Max ANC Over-Ear Headphones [ASC-024-10] (56 vs 36 hrs); Lighter than Nereus Crest X ANC Over-Ear Headphones [NER-020-09] (259 g vs 274 g) | S19: travel, commute, office | T19: in_stock | U19: 60 | V19: 229.99 | W19: 2026-08-29 | X19: N/A | Y19: N/A | Z19: N/A | AA19: N/A
A20: MOR-001-08 | B20: Morpheus | C20: Headphones & Earbuds | D20: Earbuds | E20: Morpheus Vibe Lite True Wireless Earbuds | F20: 244.99 | G20: the Vibe Lite; Morpheus Vibe Lite; Morppheus Vibe Lite; Vibe Lite earbuds | H20: 1 year limited | I20: FCC, CE, Bluetooth SIG Qualified, IPX4 | J20: N/A | K20: N/A | L20: N/A | M20: N/A | N20: USB-C charging case | O20: N/A | P20: 8 | Q20: 4 | R20: Lighter than Menoetius Pulse Pro True Wireless Earbuds [MEN-008-02] (4 g vs 5 g); Lower price than Aura Halo Ultra True Wireless Earbuds [AUR-015-08] ($244.99 vs $290.99) | S20: commute, everyday, travel | T20: in_stock | U20: 60 | V20: 258.99 | W20: 2026-08-19 | X20: N/A | Y20: N/A | Z20: N/A | AA20: N/A
A21: MOR-001-09 | B21: Morpheus | C21: Headphones & Earbuds | D21: Headphones | E21: Morpheus Onyx Air Studio Monitor Headphones | F21: 374.99 | G21: the Onyx Air; Morpheus Onyx Air; Morppheus Onyx Air; Onyx Air headphones | H21: 1 year limited | I21: CE, RoHS, Hi-Res Audio | J21: N/A | K21: N/A | L21: N/A | M21: N/A | N21: Detachable cable: 3.5mm with 6.35mm adapter | O21: N/A | P21: N/A | Q21: 375 | R21: Lower price than Aura Drift Studio Monitor Headphones [AUR-015-10] ($374.99 vs $497.99) | S21: music production, studio, podcasting | T21: in_stock | U21: 60 | V21: 430.99 | W21: 2026-09-13 | X21: N/A | Y21: N/A | Z21: N/A | AA21: N/A
A22: MOR-001-10 | B22: Morpheus | C22: Headphones & Earbuds | D22: Headphones | E22: Morpheus Onyx Lite Audiophile Planar Headphones | F22: 1063.99 | G22: the Onyx Lite; Morpheus Onyx Lite; Morpehus Onyx Lite; Onyx Lite headphones | H22: 1 year limited | I22: CE, RoHS, Hi-Res Audio | J22: N/A | K22: N/A | L22: N/A | M22: N/A | N22: Detachable cable: 3.5mm, 6.35mm and 4.4mm balanced | O22: N/A | P22: N/A | Q22: 502 | R22: Lower price than Doris Vibe Pro Audiophile Planar Headphones [DOR-004-10] ($1,063.99 vs $1,294.99); Lighter than Himeros Aeon Audiophile Planar Headphones [HIM-003-10] (502 g vs 538 g) | S22: audiophile, home listening, studio | T22: in_stock | U22: 60 | V22: 1105.99 | W22: 2026-08-26 | X22: N/A | Y22: N/A | Z22: N/A | AA22: N/A
A23: CAR-002-01 | B23: Carpo | C23: Headphones & Earbuds | D23: Headphones | E23: Carpo Apex Plus Kids Headphones | F23: 43.99 | G23: the Apex Plus; Carpo Apex Plus; Karpo Apex Plus; Apex Plus headphones | H23: 1 year limited | I23: FCC, CE, Bluetooth SIG Qualified, EN 71 Toy Safety | J23: N/A | K23: N/A | L23: N/A | M23: N/A | N23: USB-C charging, 3.5mm (85 dB limited) | O23: N/A | P23: 21 | Q23: 155 | R23: Lighter than Asclepius Drift X Kids Headphones [ASC-024-01] (155 g vs 164 g); Lower price than Hebe Apex X Kids Headphones [HEB-011-02] ($43.99 vs $50.99) | S23: kids, school, travel | T23: in_stock | U23: 30 | V23: 48.99 | W23: 2026-09-12 | X23: N/A | Y23: N/A | Z23: N/A | AA23: N/A
A24: CAR-002-02 | B24: Carpo | C24: Headphones & Earbuds | D24: Headphones | E24: Carpo Nova On-Ear Headphones | F24: 59.99 | G24: the Nova; Carpo Nova; Karpo Nova; Nova headphones | H24: 1 year limited | I24: FCC, CE, Bluetooth SIG Qualified | J24: N/A | K24: N/A | L24: N/A | M24: N/A | N24: USB-C charging, 3.5mm | O24: N/A | P24: 45 | Q24: 189 | R24: Longer battery than Tartarus Core X On-Ear Headphones [TAR-017-05] (45 vs 30 hrs); Lower price than Soteria Rift SE On-Ear Headphones [SOT-014-02] ($59.99 vs $64.99) | S24: everyday, commute, school | T24: in_stock | U24: 30 | V24: 65.99 | W24: 2026-09-11 | X24: N/A | Y24: N/A | Z24: N/A | AA24: N/A
A25: CAR-002-03 | B25: Carpo | C25: Headphones & Earbuds | D25: Headphones | E25: Carpo Quanta Air Bone Conduction Headphones | F25: 134.99 | G25: the Quanta Air; Carpo Quanta Air; Karpo Quanta Air; Quanta Air headphones | H25: 1 year limited | I25: FCC, CE, Bluetooth SIG Qualified, IP67 | J25: N/A | K25: N/A | L25: N/A | M25: N/A | N25: Magnetic USB charging | O25: N/A | P25: 10 | Q25: 30 | R25: Longer battery than Ananke Orbit Plus Bone Conduction Headphones [ANA-023-03] (10 vs 6 hrs); Lower price than Hedone Aria Bone Conduction Headphones [HED-010-05] ($134.99 vs $148.99) | S25: running, cycling, outdoor | T25: in_stock | U25: 30 | V25: 150.99 | W25: 2026-08-26 | X25: N/A | Y25: N/A | Z25: N/A | AA25: N/A
A26: CAR-002-04 | B26: Carpo | C26: Headphones & Earbuds | D26: Earbuds | E26: Carpo Lumen Pro Open-Ear Earbuds | F26: 136.99 | G26: the Lumen Pro; Carpo Lumen Pro; Caarpo Lumen Pro; Lumen Pro earbuds | H26: 1 year limited | I26: FCC, CE, Bluetooth SIG Qualified, IPX5 | J26: N/A | K26: N/A | L26: N/A | M26: N/A | N26: USB-C charging case | O26: N/A | P26: 9 | Q26: 11 | R26: Lower price than Nereus Aeon Ultra Open-Ear Earbuds [NER-020-06] ($136.99 vs $175.99); Lighter than Aura Drift Open-Ear Earbuds [AUR-015-04] (11 g vs 12 g) | S26: running, outdoor, office | T26: low_stock | U26: 30 | V26: 143.99 | W26: 2026-09-12 | X26: N/A | Y26: N/A | Z26: N/A | AA26: N/A
A27: CAR-002-05 | B27: Carpo | C27: Headphones & Earbuds | D27: Earbuds | E27: Carpo Flux Pro Sport Earbuds | F27: 153.99 | G27: the Flux Pro; Carpo Flux Pro; Carpoo Flux Pro; Flux Pro earbuds | H27: 1 year limited | I27: FCC, CE, Bluetooth SIG Qualified, IPX5 | J27: N/A | K27: N/A | L27: N/A | M27: N/A | N27: USB-C charging case | O27: N/A | P27: 7 | Q27: 9 | R27: Lower price than Chaos Flux SE Sport Earbuds [CHA-016-05] ($153.99 vs $163.99); Longer battery than Achelous Core Max Sport Earbuds [ACH-018-04] (7 vs 6 hrs) | S27: gym, running, sport | T27: in_stock | U27: 30 | V27: 166.99 | W27: 2026-09-14 | X27: N/A | Y27: N/A | Z27: N/A | AA27: N/A
A28: CAR-002-06 | B28: Carpo | C28: Headphones & Earbuds | D28: Earbuds | E28: Carpo Nova Air Wired In-Ear Monitors | F28: 183.99 | G28: the Nova Air; Carpo Nova Air; Karpo Nova Air; Nova Air earbuds | H28: 1 year limited | I28: CE, RoHS, Hi-Res Audio | J28: N/A | K28: N/A | L28: N/A | M28: N/A | N28: Detachable 2-pin cable: 3.5mm | O28: N/A | P28: N/A | Q28: 40 | R28: Lower price than Phosphorus Volt Plus Wired In-Ear Monitors [PHO-009-08] ($183.99 vs $236.99) | S28: audiophile, stage monitoring, music | T28: in_stock | U28: 30 | V28: 200.99 | W28: 2026-08-16 | X28: N/A | Y28: N/A | Z28: N/A | AA28: N/A
A29: CAR-002-07 | B29: Carpo | C29: Headphones & Earbuds | D29: Headphones | E29: Carpo Nova Plus Studio Monitor Headphones | F29: 213.99 | G29: the Nova Plus; Carpo Nova Plus; Carrpo Nova Plus; Nova Plus headphones | H29: 1 year limited | I29: CE, RoHS, Hi-Res Audio | J29: N/A | K29: N/A | L29: N/A | M29: N/A | N29: Detachable cable: 3.5mm with 6.35mm adapter | O29: N/A | P29: N/A | Q29: 361 | R29: Lower price than Hedone Sable X Studio Monitor Headphones [HED-010-08] ($213.99 vs $318.99); Lighter than Morpheus Onyx Air Studio Monitor Headphones [MOR-001-09] (361 g vs 375 g) | S29: music production, studio, podcasting | T29: in_stock | U29: 30 | V29: 225.99 | W29: 2026-09-18 | X29: N/A | Y29: N/A | Z29: N/A | AA29: N/A
A30: CAR-002-08 | B30: Carpo | C30: Headphones & Earbuds | D30: Headphones | E30: Carpo Nova ANC Over-Ear Headphones | F30: 265.99 | G30: the Nova; Carpo Nova; Carp Nova; Nova headphones | H30: 1 year limited | I30: FCC, CE, Bluetooth SIG Qualified | J30: N/A | K30: N/A | L30: N/A | M30: N/A | N30: USB-C charging and audio, 3.5mm | O30: N/A | P30: 26 | Q30: 276 | R30: Lighter than Tethys Quanta Plus ANC Over-Ear Headphones [TET-007-07] (276 g vs 278 g); Longer battery than Ananke Zen Max ANC Over-Ear Headphones [ANA-023-07] (26 vs 20 hrs) | S30: travel, commute, office | T30: low_stock | U30: 30 | V30: 284.99 | W30: 2026-08-31 | X30: N/A | Y30: N/A | Z30: N/A | AA30: N/A
A31: CAR-002-09 | B31: Carpo | C31: Headphones & Earbuds | D31: Earbuds | E31: Carpo Halo Max Sleep Earbuds | F31: 274.99 | G31: the Halo Max; Carpo Halo Max; Carrpo Halo Max; Halo Max earbuds | H31: 1 year limited | I31: FCC, CE, Bluetooth SIG Qualified | J31: N/A | K31: N/A | L31: N/A | M31: N/A | N31: USB-C charging case | O31: N/A | P31: 11 | Q31: 2 | R31: Longer battery than Clio Blaze Plus Sleep Earbuds [CLI-022-07] (11 vs 8 hrs); Lighter than Ananke Strata Air Sleep Earbuds [ANA-023-08] (2 g vs 4 g) | S31: sleep, travel, relaxation | T31: in_stock | U31: 30 | V31: 287.99 | W31: 2026-08-19 | X31: N/A | Y31: N/A | Z31: N/A | AA31: N/A
A32: CAR-002-10 | B32: Carpo | C32: Headphones & Earbuds | D32: Headphones | E32: Carpo Lumen Air Audiophile Planar Headphones | F32: 341.99 | G32: the Lumen Air; Carpo Lumen Air; Karpo Lumen Air; Lumen Air headphones | H32: 1 year limited | I32: CE, RoHS, Hi-Res Audio | J32: N/A | K32: N/A | L32: N/A | M32: N/A | N32: Detachable cable: 3.5mm, 6.35mm and 4.4mm balanced | O32: N/A | P32: N/A | Q32: 429 | R32: Lighter than Doris Vibe Pro Audiophile Planar Headphones [DOR-004-10] (429 g vs 514 g); Lower price than Glaucus Onyx Air Audiophile Planar Headphones [GLA-012-10] ($341.99 vs $865.99) | S32: audiophile, home listening, studio | T32: in_stock | U32: 30 | V32: 392.99 | W32: 2026-09-13 | X32: N/A | Y32: N/A | Z32: N/A | AA32: N/A
A33: HIM-003-01 | B33: Himeros | C33: Headphones & Earbuds | D33: Headphones | E33: Himeros Volt SE Kids Headphones | F33: 45.99 | G33: the Volt SE; Himeros Volt SE; Himreos Volt SE; Volt SE headphones | H33: 1 year limited | I33: FCC, CE, Bluetooth SIG Qualified, EN 71 Toy Safety | J33: N/A | K33: N/A | L33: N/A | M33: N/A | N33: USB-C charging, 3.5mm (85 dB limited) | O33: N/A | P33: 22 | Q33: 110 | R33: Longer battery than Carpo Apex Plus Kids Headphones [CAR-002-01] (22 vs 21 hrs); Lower price than Euphrosyne Vibe Max Kids Headphones [EUP-019-01] ($45.99 vs $52.99) | S33: kids, school, travel | T33: in_stock | U33: 30 | V33: 50.99 | W33: 2026-08-12 | X33: N/A | Y33: N/A | Z33: N/A | AA33: N/A
A34: HIM-003-02 | B34: Himeros | C34: Headphones & Earbuds | D34: Earbuds | E34: Himeros Echo SE Sport Earbuds | F34: 63.99 | G34: the Echo SE; Himeros Echo SE; Hmieros Echo SE; Echo SE earbuds | H34: 1 year limited | I34: FCC, CE, Bluetooth SIG Qualified, IP55 | J34: N/A | K34: N/A | L34: N/A | M34: N/A | N34: USB-C charging case | O34: N/A | P34: 7 | Q34: 5 | R34: Lower price than Hesperus Lumen Ultra Sport Earbuds [HES-025-05] ($63.99 vs $188.99); Lighter than Tethys Quanta Lite Sport Earbuds [TET-007-02] (5 g vs 6 g) | S34: gym, running, sport | T34: in_stock | U34: 30 | V34: 68.99 | W34: 2026-08-04 | X34: N/A | Y34: N/A | Z34: N/A | AA34: N/A
A35: HIM-003-03 | B35: Himeros | C35: Headphones & Earbuds | D35: Headphones | E35: Himeros Wave Max Bone Conduction Headphones | F35: 132.99 | G35: the Wave Max; Himeros Wave Max; Himeeros Wave Max; Wave Max headphones | H35: 1 year limited | I35: FCC, CE, Bluetooth SIG Qualified, IP67 | J35: N/A | K35: N/A | L35: N/A | M35: N/A | N35: Magnetic USB charging | O35: N/A | P35: 7 | Q35: 26 | R35: Lighter than Hedone Aria Bone Conduction Headphones [HED-010-05] (26 g vs 33 g); Longer battery than Ananke Orbit Plus Bone Conduction Headphones [ANA-023-03] (7 vs 6 hrs) | S35: running, cycling, outdoor | T35: in_stock | U35: 30 | V35: 149.99 | W35: 2026-08-01 | X35: N/A | Y35: N/A | Z35: N/A | AA35: N/A
A36: HIM-003-04 | B36: Himeros | C36: Headphones & Earbuds | D36: Earbuds | E36: Himeros Halo Pro Sleep Earbuds | F36: 161.99 | G36: the Halo Pro; Himeros Halo Pro; Hiimeros Halo Pro; Halo Pro earbuds | H36: 1 year limited | I36: FCC, CE, Bluetooth SIG Qualified | J36: N/A | K36: N/A | L36: N/A | M36: N/A | N36: USB-C charging case | O36: N/A | P36: 9 | Q36: 3 | R36: Lower price than Zeus Strata SE Sleep Earbuds [ZEU-013-07] ($161.99 vs $197.99); Lighter than Hebe Prism Pro Sleep Earbuds [HEB-011-07] (3 g vs 4 g) | S36: sleep, travel, relaxation | T36: in_stock | U36: 30 | V36: 183.99 | W36: 2026-08-29 | X36: N/A | Y36: N/A | Z36: N/A | AA36: N/A
A37: HIM-003-05 | B37: Himeros | C37: Headphones & Earbuds | D37: Earbuds | E37: Himeros Arc True Wireless Earbuds | F37: 166.99 | G37: the Arc; Himeros Arc; Himeross Arc; Arc earbuds | H37: 1 year limited | I37: FCC, CE, Bluetooth SIG Qualified, Hi-Res Audio Wireless | J37: N/A | K37: N/A | L37: N/A | M37: N/A | N37: USB-C charging case | O37: N/A | P37: 10 | Q37: 5 | R37: Longer battery than Nereus Onyx Air True Wireless Earbuds [NER-020-04] (10 vs 9 hrs); Lower price than Zeus Volt Max True Wireless Earbuds [ZEU-013-09] ($166.99 vs $289.99) | S37: commute, everyday, travel | T37: in_stock | U37: 30 | V37: 180.99 | W37: 2026-09-01 | X37: N/A | Y37: N/A | Z37: N/A | AA37: N/A
A38: HIM-003-06 | B38: Himeros | C38: Headphones & Earbuds | D38: Headphones | E38: Himeros Sable SE On-Ear Headphones | F38: 179.99 | G38: the Sable SE; Himeros Sable SE; Hiemros Sable SE; Sable SE headphones | H38: 1 year limited | I38: FCC, CE, Bluetooth SIG Qualified | J38: N/A | K38: N/A | L38: N/A | M38: N/A | N38: USB-C charging, 3.5mm | O38: N/A | P38: 55 | Q38: 179 | R38: Longer battery than Euphrosyne Blaze X On-Ear Headphones [EUP-019-03] (55 vs 35 hrs); Lighter than Tartarus Core X On-Ear Headphones [TAR-017-05] (179 g vs 208 g) | S38: everyday, commute, school | T38: in_stock | U38: 30 | V38: 204.99 | W38: 2026-09-19 | X38: N/A | Y38: N/A | Z38: N/A | AA38: N/A
A39: HIM-003-07 | B39: Himeros | C39: Headphones & Earbuds | D39: Headphones | E39: Himeros Flux Studio Monitor Headphones | F39: 195.99 | G39: the Flux; Himeros Flux; Himeroos Flux; Flux headphones | H39: 1 year limited | I39: CE, RoHS, Hi-Res Audio | J39: N/A | K39: N/A | L39: N/A | M39: N/A | N39: Detachable cable: 3.5mm with 6.35mm adapter | O39: N/A | P39: N/A | Q39: 349 | R39: Lower price than Asclepius Flux Lite Studio Monitor Headphones [ASC-024-08] ($195.99 vs $334.99); Lighter than Zeus Arc SE Studio Monitor Headphones [ZEU-013-05] (349 g vs 358 g) | S39: music production, studio, podcasting | T39: in_stock | U39: 30 | V39: 222.99 | W39: 2026-08-03 | X39: N/A | Y39: N/A | Z39: N/A | AA39: N/A
A40: HIM-003-08 | B40: Himeros | C40: Headphones & Earbuds | D40: Earbuds | E40: Himeros Aeon Lite Open-Ear Earbuds | F40: 215.99 | G40: the Aeon Lite; Himeros Aeon Lite; Himero Aeon Lite; Aeon Lite earbuds | H40: 1 year limited | I40: FCC, CE, Bluetooth SIG Qualified, IP55 | J40: N/A | K40: N/A | L40: N/A | M40: N/A | N40: USB-C charging case | O40: N/A | P40: 6 | Q40: 8 | R40: Lighter than Euphrosyne Flux Open-Ear Earbuds [EUP-019-07] (8 g vs 12 g) | S40: running, outdoor, office | T40: in_stock | U40: 30 | V40: 245.99 | W40: 2026-08-31 | X40: N/A | Y40: N/A | Z40: N/A | AA40: N/A
A41: HIM-003-09 | B41: Himeros | C41: Headphones & Earbuds | D41: Headset | E41: Himeros Sable Gaming Headset | F41: 221.99 | G41: the Sable; Himeros Sable; Himerros Sable; Sable headset | H41: 1 year limited | I41: FCC, CE, Bluetooth SIG Qualified | J41: N/A | K41: N/A | L41: N/A | M41: N/A | N41: USB-C, 3.5mm, 2.4GHz USB dongle | O41: N/A | P41: 40 | Q41: 376 | R41: Longer battery than Hedone Halo SE Gaming Headset [HED-010-01] (40 vs 37 hrs); Lower price than Glaucus Drift Pro Gaming Headset [GLA-012-07] ($221.99 vs $296.99) | S41: gaming, streaming, voice chat | T41: in_stock | U41: 30 | V41: 245.99 | W41: 2026-08-07 | X41: N/A | Y41: N/A | Z41: N/A | AA41: N/A
A42: HIM-003-10 | B42: Himeros | C42: Headphones & Earbuds | D42: Headphones | E42: Himeros Aeon Audiophile Planar Headphones | F42: 1139.99 | G42: the Aeon; Himeros Aeon; Himreos Aeon; Aeon headphones | H42: 1 year limited | I42: CE, RoHS, Hi-Res Audio | J42: N/A | K42: N/A | L42: N/A | M42: N/A | N42: Detachable cable: 3.5mm, 6.35mm and 4.4mm balanced | O42: N/A | P42: N/A | Q42: 538 | R42: Lighter than Achelous Axis Ultra Audiophile Planar Headphones [ACH-018-10] (538 g vs 550 g); Lower price than Deimos Orbit Plus Audiophile Planar Headphones [DEI-005-10] ($1,139.99 vs $1,455.99) | S42: audiophile, home listening, studio | T42: in_stock | U42: 30 | V42: 1284.99 | W42: 2026-09-03 | X42: N/A | Y42: N/A | Z42: N/A | AA42: N/A
...

Sheet Summary
A1: Company Type | B1: Companies | C1: Products | D1: Lowest Price | E1: Highest Price | F1: Average Price
A2: Headphones & Earbuds | B2: =COUNTIF(Companies!$C$14:$C$163,A2) | C2: =COUNTIF('Product Details'!$C$13:$C$1512,A2) | D2: =MINIFS('Product Details'!$F$13:$F$1512,'Product Details'!$C$13:$C$1512,A2) | E2: =MAXIFS('Product Details'!$F$13:$F$1512,'Product Details'!$C$13:$C$1512,A2) | F2: =AVERAGEIF('Product Details'!$C$13:$C$1512,A2,'Product Details'!$F$13:$F$1512)
A3: Laptops | B3: =COUNTIF(Companies!$C$14:$C$163,A3) | C3: =COUNTIF('Product Details'!$C$13:$C$1512,A3) | D3: =MINIFS('Product Details'!$F$13:$F$1512,'Product Details'!$C$13:$C$1512,A3) | E3: =MAXIFS('Product Details'!$F$13:$F$1512,'Product Details'!$C$13:$C$1512,A3) | F3: =AVERAGEIF('Product Details'!$C$13:$C$1512,A3,'Product Details'!$F$13:$F$1512)
A4: Smartphones & Tablets | B4: =COUNTIF(Companies!$C$14:$C$163,A4) | C4: =COUNTIF('Product Details'!$C$13:$C$1512,A4) | D4: =MINIFS('Product Details'!$F$13:$F$1512,'Product Details'!$C$13:$C$1512,A4) | E4: =MAXIFS('Product Details'!$F$13:$F$1512,'Product Details'!$C$13:$C$1512,A4) | F4: =AVERAGEIF('Product Details'!$C$13:$C$1512,A4,'Product Details'!$F$13:$F$1512)
A5: Computer Hardware | B5: =COUNTIF(Companies!$C$14:$C$163,A5) | C5: =COUNTIF('Product Details'!$C$13:$C$1512,A5) | D5: =MINIFS('Product Details'!$F$13:$F$1512,'Product Details'!$C$13:$C$1512,A5) | E5: =MAXIFS('Product Details'!$F$13:$F$1512,'Product Details'!$C$13:$C$1512,A5) | F5: =AVERAGEIF('Product Details'!$C$13:$C$1512,A5,'Product Details'!$F$13:$F$1512)
A6: Total | B6: =SUM(B2:B5) | C6: =SUM(C2:C5)

Sheet Login Credentials
A1: Company Portal Login Credentials
A2: Company portal logins. Temporary passwords were removed from this copy; every demo account signs in with the password cirqo-demo (DECISIONS.md #34).
A4: Company ID | B4: Company | C4: Category | D4: Username | E4: Temporary Password (removed; every demo password is cirqo-demo) | F4: Login Email | G4: Role | H4: Must Change Password | I4: Account Status
A5: CO-001 | B5: Morpheus | C5: Headphones & Earbuds | D5: morpheus.admin | F5: admin@morpheusaudio.example | G5: Brand Admin | H5: Yes | I5: Active
A6: CO-002 | B6: Carpo | C6: Headphones & Earbuds | D6: carpo.admin | F6: admin@carpoaudio.example | G6: Brand Admin | H6: Yes | I6: Active
A7: CO-003 | B7: Himeros | C7: Headphones & Earbuds | D7: himeros.admin | F7: admin@himerosaudio.example | G7: Brand Admin | H7: Yes | I7: Active
A8: CO-004 | B8: Doris | C8: Headphones & Earbuds | D8: doris.admin | F8: admin@dorisaudio.example | G8: Brand Admin | H8: Yes | I8: Active
A9: CO-005 | B9: Deimos | C9: Headphones & Earbuds | D9: deimos.admin | F9: admin@deimosaudio.example | G9: Brand Admin | H9: Yes | I9: Active
A10: CO-006 | B10: Asteria | C10: Headphones & Earbuds | D10: asteria.admin | F10: admin@asteriaaudio.example | G10: Brand Admin | H10: Yes | I10: Active
A11: CO-007 | B11: Tethys | C11: Headphones & Earbuds | D11: tethys.admin | F11: admin@tethysaudio.example | G11: Brand Admin | H11: Yes | I11: Active
A12: CO-008 | B12: Menoetius | C12: Headphones & Earbuds | D12: menoetius.admin | F12: admin@menoetiusaudio.example | G12: Brand Admin | H12: Yes | I12: Active
A13: CO-009 | B13: Phosphorus | C13: Headphones & Earbuds | D13: phosphorus.admin | F13: admin@phosphorusaudio.example | G13: Brand Admin | H13: Yes | I13: Active
A14: CO-010 | B14: Hedone | C14: Headphones & Earbuds | D14: hedone.admin | F14: admin@hedoneaudio.example | G14: Brand Admin | H14: Yes | I14: Active
A15: CO-011 | B15: Hebe | C15: Headphones & Earbuds | D15: hebe.admin | F15: admin@hebeaudio.example | G15: Brand Admin | H15: Yes | I15: Active
A16: CO-012 | B16: Glaucus | C16: Headphones & Earbuds | D16: glaucus.admin | F16: admin@glaucusaudio.example | G16: Brand Admin | H16: Yes | I16: Active
... A154: CO-150 | B154: Artemis | C154: Computer Hardware | D154: artemis.admin | F154: admin@artemishardware.example | G154: Brand Admin | H154: Yes | I154: Active
